python manage.py runserver
Microsoft Windows [Version 10.0.19042.1288]
(c) Microsoft Corporation. All rights reserved.

C:\Users\zzajaczk>python
Python 3.8.5 (tags/v3.8.5:580fbb0, Jul 20 2020, 15:57:54) [MSC v.1924 64 bit (AMD64)] on win32
Type "help", "copyright", "credits" or "license" for more information.
>>> python -m django --version
  File "<stdin>", line 1
    python -m django --version
              ^
SyntaxError: invalid syntax
>>> python -m django --version
KeyboardInterrupt
>>> exit()

C:\Users\zzajaczk>python -m django --version
C:\Users\zzajaczk\AppData\Local\Programs\Python\Python38\python.exe: No module named django

C:\Users\zzajaczk>python -m pip install django
Collecting django
  Downloading Django-3.2.8-py3-none-any.whl (7.9 MB)
     |████████████████████████████████| 7.9 MB 3.2 MB/s
Requirement already satisfied: pytz in c:\users\zzajaczk\appdata\local\programs\python\python38\lib\site-packages (from django) (2020.5)
Collecting sqlparse>=0.2.2
  Downloading sqlparse-0.4.2-py3-none-any.whl (42 kB)
     |████████████████████████████████| 42 kB 394 kB/s
Collecting asgiref<4,>=3.3.2
  Downloading asgiref-3.4.1-py3-none-any.whl (25 kB)
Installing collected packages: sqlparse, asgiref, django
Successfully installed asgiref-3.4.1 django-3.2.8 sqlparse-0.4.2
WARNING: You are using pip version 20.2.3; however, version 21.3.1 is available.
You should consider upgrading via the 'C:\Users\zzajaczk\AppData\Local\Programs\Python\Python38\python.exe -m pip install --upgrade pip' command.

C:\Users\zzajaczk>
C:\Users\zzajaczk>
C:\Users\zzajaczk>python -m django --version
3.2.8

C:\Users\zzajaczk>django -admin
'django' is not recognized as an internal or external command,
operable program or batch file.

C:\Users\zzajaczk>django-admin

Type 'django-admin help <subcommand>' for help on a specific subcommand.

Available subcommands:

[django]
    check
    compilemessages
    createcachetable
    dbshell
    diffsettings
    dumpdata
    flush
    inspectdb
    loaddata
    makemessages
    makemigrations
    migrate
    runserver
    sendtestemail
    shell
    showmigrations
    sqlflush
    sqlmigrate
    sqlsequencereset
    squashmigrations
    startapp
    startproject
    test
    testserver
Note that only Django core commands are listed as settings are not properly configured (error: Requested setting INSTALLED_APPS, but settings are not configured. You must either define the environment variable DJANGO_SETTINGS_MODULE or call settings.configure() before accessing settings.).

C:\Users\zzajaczk>cd C:\Users\zzajaczk\Documents\[Private]

C:\Users\zzajaczk\Documents\[Private]>django-admin startproject vinder

C:\Users\zzajaczk\Documents\[Private]>cd vinder

C:\Users\zzajaczk\Documents\[Private]\vinder>python manage.py runserver
Watching for file changes with StatReloader
Performing system checks...

System check identified no issues (0 silenced).

You have 18 unapplied migration(s). Your project may not work properly until you apply the migrations for app(s): admin, auth, contenttypes, sessions.
Run 'python manage.py migrate' to apply them.
October 31, 2021 - 15:21:08
Django version 3.2.8, using settings 'vinder.settings'
Starting development server at http://127.0.0.1:8000/
Quit the server with CTRL-BREAK.
[31/Oct/2021 15:21:47] "GET / HTTP/1.1" 200 10697
[31/Oct/2021 15:21:47] "GET /static/admin/css/fonts.css HTTP/1.1" 200 423
[31/Oct/2021 15:21:47] "GET /static/admin/fonts/Roboto-Light-webfont.woff HTTP/1.1" 200 85692
[31/Oct/2021 15:21:47] "GET /static/admin/fonts/Roboto-Bold-webfont.woff HTTP/1.1" 200 86184
[31/Oct/2021 15:21:47] "GET /static/admin/fonts/Roboto-Regular-webfont.woff HTTP/1.1" 200 85876
Not Found: /favicon.ico
[31/Oct/2021 15:21:47] "GET /favicon.ico HTTP/1.1" 404 2110

C:\Users\zzajaczk\Documents\[Private]\vinder>
C:\Users\zzajaczk\Documents\[Private]\vinder>
C:\Users\zzajaczk\Documents\[Private]\vinder>
C:\Users\zzajaczk\Documents\[Private]\vinder>
C:\Users\zzajaczk\Documents\[Private]\vinder>
C:\Users\zzajaczk\Documents\[Private]\vinder>python manage.py startapp
usage: manage.py startapp [-h] [--template TEMPLATE] [--extension EXTENSIONS] [--name FILES] [--version]
                          [-v {0,1,2,3}] [--settings SETTINGS] [--pythonpath PYTHONPATH] [--traceback] [--no-color]
                          [--force-color]
                          name [directory]
manage.py startapp: error: You must provide an application name.

C:\Users\zzajaczk\Documents\[Private]\vinder>python manage.py startapp vinder_rest_api

C:\Users\zzajaczk\Documents\[Private]\vinder>python manage.py runserver
Watching for file changes with StatReloader
Performing system checks...

System check identified no issues (0 silenced).

You have 18 unapplied migration(s). Your project may not work properly until you apply the migrations for app(s): admin, auth, contenttypes, sessions.
Run 'python manage.py migrate' to apply them.
October 31, 2021 - 15:24:38
Django version 3.2.8, using settings 'vinder.settings'
Starting development server at http://127.0.0.1:8000/
Quit the server with CTRL-BREAK.
C:\Users\zzajaczk\Documents\[Private]\vinder\vinder\urls.py changed, reloading.
Watching for file changes with StatReloader
Performing system checks...

Exception in thread django-main-thread:
Traceback (most recent call last):
  File "C:\Users\zzajaczk\AppData\Local\Programs\Python\Python38\lib\threading.py", line 932, in _bootstrap_inner
    self.run()
  File "C:\Users\zzajaczk\AppData\Local\Programs\Python\Python38\lib\threading.py", line 870, in run
    self._target(*self._args, **self._kwargs)
  File "C:\Users\zzajaczk\AppData\Local\Programs\Python\Python38\lib\site-packages\django\utils\autoreload.py", line 64, in wrapper
    fn(*args, **kwargs)
  File "C:\Users\zzajaczk\AppData\Local\Programs\Python\Python38\lib\site-packages\django\core\management\commands\runserver.py", line 118, in inner_run
    self.check(display_num_errors=True)
  File "C:\Users\zzajaczk\AppData\Local\Programs\Python\Python38\lib\site-packages\django\core\management\base.py", line 419, in check
    all_issues = checks.run_checks(
  File "C:\Users\zzajaczk\AppData\Local\Programs\Python\Python38\lib\site-packages\django\core\checks\registry.py", line 76, in run_checks
    new_errors = check(app_configs=app_configs, databases=databases)
  File "C:\Users\zzajaczk\AppData\Local\Programs\Python\Python38\lib\site-packages\django\core\checks\urls.py", line 13, in check_url_config
    return check_resolver(resolver)
  File "C:\Users\zzajaczk\AppData\Local\Programs\Python\Python38\lib\site-packages\django\core\checks\urls.py", line 23, in check_resolver
    return check_method()
  File "C:\Users\zzajaczk\AppData\Local\Programs\Python\Python38\lib\site-packages\django\urls\resolvers.py", line 412, in check
    for pattern in self.url_patterns:
  File "C:\Users\zzajaczk\AppData\Local\Programs\Python\Python38\lib\site-packages\django\utils\functional.py", line 48, in __get__
    res = instance.__dict__[self.name] = self.func(instance)
  File "C:\Users\zzajaczk\AppData\Local\Programs\Python\Python38\lib\site-packages\django\urls\resolvers.py", line 598, in url_patterns
    patterns = getattr(self.urlconf_module, "urlpatterns", self.urlconf_module)
  File "C:\Users\zzajaczk\AppData\Local\Programs\Python\Python38\lib\site-packages\django\utils\functional.py", line 48, in __get__
    res = instance.__dict__[self.name] = self.func(instance)
  File "C:\Users\zzajaczk\AppData\Local\Programs\Python\Python38\lib\site-packages\django\urls\resolvers.py", line 591, in urlconf_module
    return import_module(self.urlconf_name)
  File "C:\Users\zzajaczk\AppData\Local\Programs\Python\Python38\lib\importlib\__init__.py", line 127, in import_module
    return _bootstrap._gcd_import(name[level:], package, level)
  File "<frozen importlib._bootstrap>", line 1014, in _gcd_import
  File "<frozen importlib._bootstrap>", line 991, in _find_and_load
  File "<frozen importlib._bootstrap>", line 975, in _find_and_load_unlocked
  File "<frozen importlib._bootstrap>", line 671, in _load_unlocked
  File "<frozen importlib._bootstrap_external>", line 783, in exec_module
  File "<frozen importlib._bootstrap>", line 219, in _call_with_frames_removed
  File "C:\Users\zzajaczk\Documents\[Private]\vinder\vinder\urls.py", line 20, in <module>
    path("vinder/", include("vinder_rest_api.urls")),
  File "C:\Users\zzajaczk\AppData\Local\Programs\Python\Python38\lib\site-packages\django\urls\conf.py", line 34, in include
    urlconf_module = import_module(urlconf_module)
  File "C:\Users\zzajaczk\AppData\Local\Programs\Python\Python38\lib\importlib\__init__.py", line 127, in import_module
    return _bootstrap._gcd_import(name[level:], package, level)
  File "<frozen importlib._bootstrap>", line 1014, in _gcd_import
  File "<frozen importlib._bootstrap>", line 991, in _find_and_load
  File "<frozen importlib._bootstrap>", line 975, in _find_and_load_unlocked
  File "<frozen importlib._bootstrap>", line 671, in _load_unlocked
  File "<frozen importlib._bootstrap_external>", line 783, in exec_module
  File "<frozen importlib._bootstrap>", line 219, in _call_with_frames_removed
  File "C:\Users\zzajaczk\Documents\[Private]\vinder\vinder_rest_api\urls.py", line 5, in <module>
    path("",views.dupa,name= "DUPA_strona_glowna")
AttributeError: module 'vinder_rest_api.views' has no attribute 'dupa'
C:\Users\zzajaczk\Documents\[Private]\vinder\vinder_rest_api\views.py changed, reloading.
Watching for file changes with StatReloader
Performing system checks...

Exception in thread django-main-thread:
Traceback (most recent call last):
  File "C:\Users\zzajaczk\AppData\Local\Programs\Python\Python38\lib\site-packages\django\urls\resolvers.py", line 600, in url_patterns
    iter(patterns)
TypeError: 'module' object is not iterable

The above exception was the direct cause of the following exception:

Traceback (most recent call last):
  File "C:\Users\zzajaczk\AppData\Local\Programs\Python\Python38\lib\threading.py", line 932, in _bootstrap_inner
    self.run()
  File "C:\Users\zzajaczk\AppData\Local\Programs\Python\Python38\lib\threading.py", line 870, in run
    self._target(*self._args, **self._kwargs)
  File "C:\Users\zzajaczk\AppData\Local\Programs\Python\Python38\lib\site-packages\django\utils\autoreload.py", line 64, in wrapper
    fn(*args, **kwargs)
  File "C:\Users\zzajaczk\AppData\Local\Programs\Python\Python38\lib\site-packages\django\core\management\commands\runserver.py", line 118, in inner_run
    self.check(display_num_errors=True)
  File "C:\Users\zzajaczk\AppData\Local\Programs\Python\Python38\lib\site-packages\django\core\management\base.py", line 419, in check
    all_issues = checks.run_checks(
  File "C:\Users\zzajaczk\AppData\Local\Programs\Python\Python38\lib\site-packages\django\core\checks\registry.py", line 76, in run_checks
    new_errors = check(app_configs=app_configs, databases=databases)
  File "C:\Users\zzajaczk\AppData\Local\Programs\Python\Python38\lib\site-packages\django\core\checks\urls.py", line 13, in check_url_config
    return check_resolver(resolver)
  File "C:\Users\zzajaczk\AppData\Local\Programs\Python\Python38\lib\site-packages\django\core\checks\urls.py", line 23, in check_resolver
    return check_method()
  File "C:\Users\zzajaczk\AppData\Local\Programs\Python\Python38\lib\site-packages\django\urls\resolvers.py", line 413, in check
    messages.extend(check_resolver(pattern))
  File "C:\Users\zzajaczk\AppData\Local\Programs\Python\Python38\lib\site-packages\django\core\checks\urls.py", line 23, in check_resolver
    return check_method()
  File "C:\Users\zzajaczk\AppData\Local\Programs\Python\Python38\lib\site-packages\django\urls\resolvers.py", line 412, in check
    for pattern in self.url_patterns:
  File "C:\Users\zzajaczk\AppData\Local\Programs\Python\Python38\lib\site-packages\django\utils\functional.py", line 48, in __get__
    res = instance.__dict__[self.name] = self.func(instance)
  File "C:\Users\zzajaczk\AppData\Local\Programs\Python\Python38\lib\site-packages\django\urls\resolvers.py", line 607, in url_patterns
    raise ImproperlyConfigured(msg.format(name=self.urlconf_name)) from e
django.core.exceptions.ImproperlyConfigured: The included URLconf '<module 'vinder_rest_api.urls' from 'C:\\Users\\zzajaczk\\Documents\\[Private]\\vinder\\vinder_rest_api\\urls.py'>' does not appear to have any patterns in it. If you see valid patterns in the file then the issue is probably caused by a circular import.
C:\Users\zzajaczk\Documents\[Private]\vinder\vinder\urls.py changed, reloading.
Watching for file changes with StatReloader
Performing system checks...

Exception in thread django-main-thread:
Traceback (most recent call last):
  File "C:\Users\zzajaczk\AppData\Local\Programs\Python\Python38\lib\site-packages\django\urls\resolvers.py", line 600, in url_patterns
    iter(patterns)
TypeError: 'module' object is not iterable

The above exception was the direct cause of the following exception:

Traceback (most recent call last):
  File "C:\Users\zzajaczk\AppData\Local\Programs\Python\Python38\lib\threading.py", line 932, in _bootstrap_inner
    self.run()
  File "C:\Users\zzajaczk\AppData\Local\Programs\Python\Python38\lib\threading.py", line 870, in run
    self._target(*self._args, **self._kwargs)
  File "C:\Users\zzajaczk\AppData\Local\Programs\Python\Python38\lib\site-packages\django\utils\autoreload.py", line 64, in wrapper
    fn(*args, **kwargs)
  File "C:\Users\zzajaczk\AppData\Local\Programs\Python\Python38\lib\site-packages\django\core\management\commands\runserver.py", line 118, in inner_run
    self.check(display_num_errors=True)
  File "C:\Users\zzajaczk\AppData\Local\Programs\Python\Python38\lib\site-packages\django\core\management\base.py", line 419, in check
    all_issues = checks.run_checks(
  File "C:\Users\zzajaczk\AppData\Local\Programs\Python\Python38\lib\site-packages\django\core\checks\registry.py", line 76, in run_checks
    new_errors = check(app_configs=app_configs, databases=databases)
  File "C:\Users\zzajaczk\AppData\Local\Programs\Python\Python38\lib\site-packages\django\core\checks\urls.py", line 13, in check_url_config
    return check_resolver(resolver)
  File "C:\Users\zzajaczk\AppData\Local\Programs\Python\Python38\lib\site-packages\django\core\checks\urls.py", line 23, in check_resolver
    return check_method()
  File "C:\Users\zzajaczk\AppData\Local\Programs\Python\Python38\lib\site-packages\django\urls\resolvers.py", line 413, in check
    messages.extend(check_resolver(pattern))
  File "C:\Users\zzajaczk\AppData\Local\Programs\Python\Python38\lib\site-packages\django\core\checks\urls.py", line 23, in check_resolver
    return check_method()
  File "C:\Users\zzajaczk\AppData\Local\Programs\Python\Python38\lib\site-packages\django\urls\resolvers.py", line 412, in check
    for pattern in self.url_patterns:
  File "C:\Users\zzajaczk\AppData\Local\Programs\Python\Python38\lib\site-packages\django\utils\functional.py", line 48, in __get__
    res = instance.__dict__[self.name] = self.func(instance)
  File "C:\Users\zzajaczk\AppData\Local\Programs\Python\Python38\lib\site-packages\django\urls\resolvers.py", line 607, in url_patterns
    raise ImproperlyConfigured(msg.format(name=self.urlconf_name)) from e
django.core.exceptions.ImproperlyConfigured: The included URLconf '<module 'vinder_rest_api.urls' from 'C:\\Users\\zzajaczk\\Documents\\[Private]\\vinder\\vinder_rest_api\\urls.py'>' does not appear to have any patterns in it. If you see valid patterns in the file then the issue is probably caused by a circular import.
C:\Users\zzajaczk\Documents\[Private]\vinder\vinder_rest_api\urls.py changed, reloading.
Watching for file changes with StatReloader
Performing system checks...

Exception in thread django-main-thread:
Traceback (most recent call last):
  File "C:\Users\zzajaczk\AppData\Local\Programs\Python\Python38\lib\site-packages\django\urls\resolvers.py", line 600, in url_patterns
    iter(patterns)
TypeError: 'module' object is not iterable

The above exception was the direct cause of the following exception:

Traceback (most recent call last):
  File "C:\Users\zzajaczk\AppData\Local\Programs\Python\Python38\lib\threading.py", line 932, in _bootstrap_inner
    self.run()
  File "C:\Users\zzajaczk\AppData\Local\Programs\Python\Python38\lib\threading.py", line 870, in run
    self._target(*self._args, **self._kwargs)
  File "C:\Users\zzajaczk\AppData\Local\Programs\Python\Python38\lib\site-packages\django\utils\autoreload.py", line 64, in wrapper
    fn(*args, **kwargs)
  File "C:\Users\zzajaczk\AppData\Local\Programs\Python\Python38\lib\site-packages\django\core\management\commands\runserver.py", line 118, in inner_run
    self.check(display_num_errors=True)
  File "C:\Users\zzajaczk\AppData\Local\Programs\Python\Python38\lib\site-packages\django\core\management\base.py", line 419, in check
    all_issues = checks.run_checks(
  File "C:\Users\zzajaczk\AppData\Local\Programs\Python\Python38\lib\site-packages\django\core\checks\registry.py", line 76, in run_checks
    new_errors = check(app_configs=app_configs, databases=databases)
  File "C:\Users\zzajaczk\AppData\Local\Programs\Python\Python38\lib\site-packages\django\core\checks\urls.py", line 13, in check_url_config
    return check_resolver(resolver)
  File "C:\Users\zzajaczk\AppData\Local\Programs\Python\Python38\lib\site-packages\django\core\checks\urls.py", line 23, in check_resolver
    return check_method()
  File "C:\Users\zzajaczk\AppData\Local\Programs\Python\Python38\lib\site-packages\django\urls\resolvers.py", line 413, in check
    messages.extend(check_resolver(pattern))
  File "C:\Users\zzajaczk\AppData\Local\Programs\Python\Python38\lib\site-packages\django\core\checks\urls.py", line 23, in check_resolver
    return check_method()
  File "C:\Users\zzajaczk\AppData\Local\Programs\Python\Python38\lib\site-packages\django\urls\resolvers.py", line 412, in check
    for pattern in self.url_patterns:
  File "C:\Users\zzajaczk\AppData\Local\Programs\Python\Python38\lib\site-packages\django\utils\functional.py", line 48, in __get__
    res = instance.__dict__[self.name] = self.func(instance)
  File "C:\Users\zzajaczk\AppData\Local\Programs\Python\Python38\lib\site-packages\django\urls\resolvers.py", line 607, in url_patterns
    raise ImproperlyConfigured(msg.format(name=self.urlconf_name)) from e
django.core.exceptions.ImproperlyConfigured: The included URLconf '<module 'vinder_rest_api.urls' from 'C:\\Users\\zzajaczk\\Documents\\[Private]\\vinder\\vinder_rest_api\\urls.py'>' does not appear to have any patterns in it. If you see valid patterns in the file then the issue is probably caused by a circular import.
C:\Users\zzajaczk\Documents\[Private]\vinder\vinder\urls.py changed, reloading.
Watching for file changes with StatReloader
Performing system checks...

Exception in thread django-main-thread:
Traceback (most recent call last):
  File "C:\Users\zzajaczk\AppData\Local\Programs\Python\Python38\lib\site-packages\django\urls\resolvers.py", line 600, in url_patterns
    iter(patterns)
TypeError: 'module' object is not iterable

The above exception was the direct cause of the following exception:

Traceback (most recent call last):
  File "C:\Users\zzajaczk\AppData\Local\Programs\Python\Python38\lib\threading.py", line 932, in _bootstrap_inner
    self.run()
  File "C:\Users\zzajaczk\AppData\Local\Programs\Python\Python38\lib\threading.py", line 870, in run
    self._target(*self._args, **self._kwargs)
  File "C:\Users\zzajaczk\AppData\Local\Programs\Python\Python38\lib\site-packages\django\utils\autoreload.py", line 64, in wrapper
    fn(*args, **kwargs)
  File "C:\Users\zzajaczk\AppData\Local\Programs\Python\Python38\lib\site-packages\django\core\management\commands\runserver.py", line 118, in inner_run
    self.check(display_num_errors=True)
  File "C:\Users\zzajaczk\AppData\Local\Programs\Python\Python38\lib\site-packages\django\core\management\base.py", line 419, in check
    all_issues = checks.run_checks(
  File "C:\Users\zzajaczk\AppData\Local\Programs\Python\Python38\lib\site-packages\django\core\checks\registry.py", line 76, in run_checks
    new_errors = check(app_configs=app_configs, databases=databases)
  File "C:\Users\zzajaczk\AppData\Local\Programs\Python\Python38\lib\site-packages\django\core\checks\urls.py", line 13, in check_url_config
    return check_resolver(resolver)
  File "C:\Users\zzajaczk\AppData\Local\Programs\Python\Python38\lib\site-packages\django\core\checks\urls.py", line 23, in check_resolver
    return check_method()
  File "C:\Users\zzajaczk\AppData\Local\Programs\Python\Python38\lib\site-packages\django\urls\resolvers.py", line 413, in check
    messages.extend(check_resolver(pattern))
  File "C:\Users\zzajaczk\AppData\Local\Programs\Python\Python38\lib\site-packages\django\core\checks\urls.py", line 23, in check_resolver
    return check_method()
  File "C:\Users\zzajaczk\AppData\Local\Programs\Python\Python38\lib\site-packages\django\urls\resolvers.py", line 412, in check
    for pattern in self.url_patterns:
  File "C:\Users\zzajaczk\AppData\Local\Programs\Python\Python38\lib\site-packages\django\utils\functional.py", line 48, in __get__
    res = instance.__dict__[self.name] = self.func(instance)
  File "C:\Users\zzajaczk\AppData\Local\Programs\Python\Python38\lib\site-packages\django\urls\resolvers.py", line 607, in url_patterns
    raise ImproperlyConfigured(msg.format(name=self.urlconf_name)) from e
django.core.exceptions.ImproperlyConfigured: The included URLconf '<module 'vinder_rest_api.urls' from 'C:\\Users\\zzajaczk\\Documents\\[Private]\\vinder\\vinder_rest_api\\urls.py'>' does not appear to have any patterns in it. If you see valid patterns in the file then the issue is probably caused by a circular import.

C:\Users\zzajaczk\Documents\[Private]\vinder>python manage.py runserver
Watching for file changes with StatReloader
Performing system checks...

Exception in thread django-main-thread:
Traceback (most recent call last):
  File "C:\Users\zzajaczk\AppData\Local\Programs\Python\Python38\lib\site-packages\django\urls\resolvers.py", line 600, in url_patterns
    iter(patterns)
TypeError: 'module' object is not iterable

The above exception was the direct cause of the following exception:

Traceback (most recent call last):
  File "C:\Users\zzajaczk\AppData\Local\Programs\Python\Python38\lib\threading.py", line 932, in _bootstrap_inner
    self.run()
  File "C:\Users\zzajaczk\AppData\Local\Programs\Python\Python38\lib\threading.py", line 870, in run
    self._target(*self._args, **self._kwargs)
  File "C:\Users\zzajaczk\AppData\Local\Programs\Python\Python38\lib\site-packages\django\utils\autoreload.py", line 64, in wrapper
    fn(*args, **kwargs)
  File "C:\Users\zzajaczk\AppData\Local\Programs\Python\Python38\lib\site-packages\django\core\management\commands\runserver.py", line 118, in inner_run
    self.check(display_num_errors=True)
  File "C:\Users\zzajaczk\AppData\Local\Programs\Python\Python38\lib\site-packages\django\core\management\base.py", line 419, in check
    all_issues = checks.run_checks(
  File "C:\Users\zzajaczk\AppData\Local\Programs\Python\Python38\lib\site-packages\django\core\checks\registry.py", line 76, in run_checks
    new_errors = check(app_configs=app_configs, databases=databases)
  File "C:\Users\zzajaczk\AppData\Local\Programs\Python\Python38\lib\site-packages\django\core\checks\urls.py", line 13, in check_url_config
    return check_resolver(resolver)
  File "C:\Users\zzajaczk\AppData\Local\Programs\Python\Python38\lib\site-packages\django\core\checks\urls.py", line 23, in check_resolver
    return check_method()
  File "C:\Users\zzajaczk\AppData\Local\Programs\Python\Python38\lib\site-packages\django\urls\resolvers.py", line 413, in check
    messages.extend(check_resolver(pattern))
  File "C:\Users\zzajaczk\AppData\Local\Programs\Python\Python38\lib\site-packages\django\core\checks\urls.py", line 23, in check_resolver
    return check_method()
  File "C:\Users\zzajaczk\AppData\Local\Programs\Python\Python38\lib\site-packages\django\urls\resolvers.py", line 412, in check
    for pattern in self.url_patterns:
  File "C:\Users\zzajaczk\AppData\Local\Programs\Python\Python38\lib\site-packages\django\utils\functional.py", line 48, in __get__
    res = instance.__dict__[self.name] = self.func(instance)
  File "C:\Users\zzajaczk\AppData\Local\Programs\Python\Python38\lib\site-packages\django\urls\resolvers.py", line 607, in url_patterns
    raise ImproperlyConfigured(msg.format(name=self.urlconf_name)) from e
django.core.exceptions.ImproperlyConfigured: The included URLconf '<module 'vinder_rest_api.urls' from 'C:\\Users\\zzajaczk\\Documents\\[Private]\\vinder\\vinder_rest_api\\urls.py'>' does not appear to have any patterns in it. If you see valid patterns in the file then the issue is probably caused by a circular import.
C:\Users\zzajaczk\Documents\[Private]\vinder\vinder_rest_api\urls.py changed, reloading.
Watching for file changes with StatReloader
Performing system checks...

Exception in thread django-main-thread:
Traceback (most recent call last):
  File "C:\Users\zzajaczk\AppData\Local\Programs\Python\Python38\lib\site-packages\django\urls\resolvers.py", line 600, in url_patterns
    iter(patterns)
TypeError: 'module' object is not iterable

The above exception was the direct cause of the following exception:

Traceback (most recent call last):
  File "C:\Users\zzajaczk\AppData\Local\Programs\Python\Python38\lib\threading.py", line 932, in _bootstrap_inner
    self.run()
  File "C:\Users\zzajaczk\AppData\Local\Programs\Python\Python38\lib\threading.py", line 870, in run
    self._target(*self._args, **self._kwargs)
  File "C:\Users\zzajaczk\AppData\Local\Programs\Python\Python38\lib\site-packages\django\utils\autoreload.py", line 64, in wrapper
    fn(*args, **kwargs)
  File "C:\Users\zzajaczk\AppData\Local\Programs\Python\Python38\lib\site-packages\django\core\management\commands\runserver.py", line 118, in inner_run
    self.check(display_num_errors=True)
  File "C:\Users\zzajaczk\AppData\Local\Programs\Python\Python38\lib\site-packages\django\core\management\base.py", line 419, in check
    all_issues = checks.run_checks(
  File "C:\Users\zzajaczk\AppData\Local\Programs\Python\Python38\lib\site-packages\django\core\checks\registry.py", line 76, in run_checks
    new_errors = check(app_configs=app_configs, databases=databases)
  File "C:\Users\zzajaczk\AppData\Local\Programs\Python\Python38\lib\site-packages\django\core\checks\urls.py", line 13, in check_url_config
    return check_resolver(resolver)
  File "C:\Users\zzajaczk\AppData\Local\Programs\Python\Python38\lib\site-packages\django\core\checks\urls.py", line 23, in check_resolver
    return check_method()
  File "C:\Users\zzajaczk\AppData\Local\Programs\Python\Python38\lib\site-packages\django\urls\resolvers.py", line 413, in check
    messages.extend(check_resolver(pattern))
  File "C:\Users\zzajaczk\AppData\Local\Programs\Python\Python38\lib\site-packages\django\core\checks\urls.py", line 23, in check_resolver
    return check_method()
  File "C:\Users\zzajaczk\AppData\Local\Programs\Python\Python38\lib\site-packages\django\urls\resolvers.py", line 412, in check
    for pattern in self.url_patterns:
  File "C:\Users\zzajaczk\AppData\Local\Programs\Python\Python38\lib\site-packages\django\utils\functional.py", line 48, in __get__
    res = instance.__dict__[self.name] = self.func(instance)
  File "C:\Users\zzajaczk\AppData\Local\Programs\Python\Python38\lib\site-packages\django\urls\resolvers.py", line 607, in url_patterns
    raise ImproperlyConfigured(msg.format(name=self.urlconf_name)) from e
django.core.exceptions.ImproperlyConfigured: The included URLconf '<module 'vinder_rest_api.urls' from 'C:\\Users\\zzajaczk\\Documents\\[Private]\\vinder\\vinder_rest_api\\urls.py'>' does not appear to have any patterns in it. If you see valid patterns in the file then the issue is probably caused by a circular import.
C:\Users\zzajaczk\Documents\[Private]\vinder\vinder_rest_api\urls.py changed, reloading.
Watching for file changes with StatReloader
Performing system checks...

System check identified no issues (0 silenced).

You have 18 unapplied migration(s). Your project may not work properly until you apply the migrations for app(s): admin, auth, contenttypes, sessions.
Run 'python manage.py migrate' to apply them.
October 31, 2021 - 15:35:45
Django version 3.2.8, using settings 'vinder.settings'
Starting development server at http://127.0.0.1:8000/
Quit the server with CTRL-BREAK.
Not Found: /
[31/Oct/2021 15:36:46] "GET / HTTP/1.1" 404 2166
[31/Oct/2021 15:37:29] "GET /vinder HTTP/1.1" 301 0
[31/Oct/2021 15:37:29] "GET /vinder/ HTTP/1.1" 200 28
C:\Users\zzajaczk\Documents\[Private]\vinder\vinder_rest_api\urls.py changed, reloading.
Watching for file changes with StatReloader
Performing system checks...

System check identified no issues (0 silenced).

You have 18 unapplied migration(s). Your project may not work properly until you apply the migrations for app(s): admin, auth, contenttypes, sessions.
Run 'python manage.py migrate' to apply them.
October 31, 2021 - 15:38:54
Django version 3.2.8, using settings 'vinder.settings'
Starting development server at http://127.0.0.1:8000/
Quit the server with CTRL-BREAK.
[31/Oct/2021 15:38:54] "GET /vinder/test HTTP/1.1" 200 28
Not Found: /vinder/
[31/Oct/2021 15:39:00] "GET /vinder/ HTTP/1.1" 404 2283
[31/Oct/2021 15:39:03] "GET /vinder/test HTTP/1.1" 200 28
C:\Users\zzajaczk\Documents\[Private]\vinder\vinder_rest_api\views.py changed, reloading.
Watching for file changes with StatReloader
Performing system checks...

System check identified no issues (0 silenced).

You have 18 unapplied migration(s). Your project may not work properly until you apply the migrations for app(s): admin, auth, contenttypes, sessions.
Run 'python manage.py migrate' to apply them.
October 31, 2021 - 15:44:11
Django version 3.2.8, using settings 'vinder.settings'
Starting development server at http://127.0.0.1:8000/
Quit the server with CTRL-BREAK.
C:\Users\zzajaczk\Documents\[Private]\vinder\vinder_rest_api\views.py changed, reloading.
Watching for file changes with StatReloader
Performing system checks...

System check identified no issues (0 silenced).

You have 18 unapplied migration(s). Your project may not work properly until you apply the migrations for app(s): admin, auth, contenttypes, sessions.
Run 'python manage.py migrate' to apply them.
October 31, 2021 - 15:44:37
Django version 3.2.8, using settings 'vinder.settings'
Starting development server at http://127.0.0.1:8000/
Quit the server with CTRL-BREAK.
C:\Users\zzajaczk\Documents\[Private]\vinder\vinder_rest_api\urls.py changed, reloading.
Watching for file changes with StatReloader
Performing system checks...

System check identified no issues (0 silenced).

You have 18 unapplied migration(s). Your project may not work properly until you apply the migrations for app(s): admin, auth, contenttypes, sessions.
Run 'python manage.py migrate' to apply them.
October 31, 2021 - 15:45:26
Django version 3.2.8, using settings 'vinder.settings'
Starting development server at http://127.0.0.1:8000/
Quit the server with CTRL-BREAK.
[31/Oct/2021 15:45:38] "GET /vinder/test2 HTTP/1.1" 200 32

C:\Users\zzajaczk\Documents\[Private]\vinder>
C:\Users\zzajaczk\Documents\[Private]\vinder>
C:\Users\zzajaczk\Documents\[Private]\vinder>python manage.py migrate
Operations to perform:
  Apply all migrations: admin, auth, contenttypes, sessions
Running migrations:
  Applying contenttypes.0001_initial... OK
  Applying auth.0001_initial... OK
  Applying admin.0001_initial... OK
  Applying admin.0002_logentry_remove_auto_add... OK
  Applying admin.0003_logentry_add_action_flag_choices... OK
  Applying contenttypes.0002_remove_content_type_name... OK
  Applying auth.0002_alter_permission_name_max_length... OK
  Applying auth.0003_alter_user_email_max_length... OK
  Applying auth.0004_alter_user_username_opts... OK
  Applying auth.0005_alter_user_last_login_null... OK
  Applying auth.0006_require_contenttypes_0002... OK
  Applying auth.0007_alter_validators_add_error_messages... OK
  Applying auth.0008_alter_user_username_max_length... OK
  Applying auth.0009_alter_user_last_name_max_length... OK
  Applying auth.0010_alter_group_name_max_length... OK
  Applying auth.0011_update_proxy_permissions... OK
  Applying auth.0012_alter_user_first_name_max_length... OK
  Applying sessions.0001_initial... OK

C:\Users\zzajaczk\Documents\[Private]\vinder>python manage.py makemigration
Unknown command: 'makemigration'. Did you mean makemigrations?
Type 'manage.py help' for usage.

C:\Users\zzajaczk\Documents\[Private]\vinder>python manage.py makemigrations
SystemCheckError: System check identified some issues:

ERRORS:
vinder_rest_api.VinderSession.init_user: (fields.E304) Reverse accessor for 'vinder_rest_api.VinderSession.init_user' clashes with reverse accessor for 'vinder_rest_api.VinderSession.other_user'.
        HINT: Add or change a related_name argument to the definition for 'vinder_rest_api.VinderSession.init_user' or 'vinder_rest_api.VinderSession.other_user'.
vinder_rest_api.VinderSession.other_user: (fields.E304) Reverse accessor for 'vinder_rest_api.VinderSession.other_user' clashes with reverse accessor for 'vinder_rest_api.VinderSession.init_user'.
        HINT: Add or change a related_name argument to the definition for 'vinder_rest_api.VinderSession.other_user' or 'vinder_rest_api.VinderSession.init_user'.

C:\Users\zzajaczk\Documents\[Private]\vinder>python manage.py makemigrations
Migrations for 'vinder_rest_api':
  vinder_rest_api\migrations\0001_initial.py
    - Create model VinderSession

C:\Users\zzajaczk\Documents\[Private]\vinder>python manage.py migrate
Operations to perform:
  Apply all migrations: admin, auth, contenttypes, sessions, vinder_rest_api
Running migrations:
  Applying vinder_rest_api.0001_initial... OK

C:\Users\zzajaczk\Documents\[Private]\vinder>python manage.py creatsuperuser
Unknown command: 'creatsuperuser'. Did you mean createsuperuser?
Type 'manage.py help' for usage.

C:\Users\zzajaczk\Documents\[Private]\vinder>python manage.py createsuperuser
Username (leave blank to use 'zzajaczk'): admin
Email address:
Password:
Password (again):
The password is too similar to the username.
This password is too short. It must contain at least 8 characters.
This password is too common.
Bypass password validation and create user anyway? [y/N]: y
Superuser created successfully.

C:\Users\zzajaczk\Documents\[Private]\vinder>python manage.py runserver
Watching for file changes with StatReloader
Performing system checks...

System check identified no issues (0 silenced).
October 31, 2021 - 16:14:37
Django version 3.2.8, using settings 'vinder.settings'
Starting development server at http://127.0.0.1:8000/
Quit the server with CTRL-BREAK.
[31/Oct/2021 16:15:27] "GET /admin HTTP/1.1" 301 0
[31/Oct/2021 16:15:27] "GET /admin/ HTTP/1.1" 302 0
[31/Oct/2021 16:15:27] "GET /admin/login/?next=/admin/ HTTP/1.1" 200 2214
[31/Oct/2021 16:15:27] "GET /static/admin/css/base.css HTTP/1.1" 200 19513
[31/Oct/2021 16:15:27] "GET /static/admin/css/login.css HTTP/1.1" 200 939
[31/Oct/2021 16:15:27] "GET /static/admin/css/nav_sidebar.css HTTP/1.1" 200 2271
[31/Oct/2021 16:15:27] "GET /static/admin/css/responsive.css HTTP/1.1" 200 18545
[31/Oct/2021 16:15:27] "GET /static/admin/js/nav_sidebar.js HTTP/1.1" 200 1360
[31/Oct/2021 16:15:27] "GET /static/admin/css/fonts.css HTTP/1.1" 304 0
[31/Oct/2021 16:15:27] "GET /static/admin/fonts/Roboto-Regular-webfont.woff HTTP/1.1" 304 0
[31/Oct/2021 16:15:27] "GET /static/admin/fonts/Roboto-Light-webfont.woff HTTP/1.1" 304 0
[31/Oct/2021 16:15:30] "POST /admin/login/?next=/admin/ HTTP/1.1" 302 0
[31/Oct/2021 16:15:30] "GET /admin/ HTTP/1.1" 200 3326
[31/Oct/2021 16:15:31] "GET /static/admin/css/dashboard.css HTTP/1.1" 200 380
[31/Oct/2021 16:15:31] "GET /static/admin/img/icon-changelink.svg HTTP/1.1" 200 380
[31/Oct/2021 16:15:31] "GET /static/admin/img/icon-addlink.svg HTTP/1.1" 200 331
[31/Oct/2021 16:15:31] "GET /static/admin/fonts/Roboto-Bold-webfont.woff HTTP/1.1" 304 0
C:\Users\zzajaczk\Documents\[Private]\vinder\vinder\urls.py changed, reloading.
Watching for file changes with StatReloader
Performing system checks...

System check identified no issues (0 silenced).
October 31, 2021 - 16:17:37
Django version 3.2.8, using settings 'vinder.settings'
Starting development server at http://127.0.0.1:8000/
Quit the server with CTRL-BREAK.
[31/Oct/2021 16:17:43] "GET /admin/ HTTP/1.1" 200 3326
[31/Oct/2021 16:17:53] "GET /admin/ HTTP/1.1" 200 3326
[31/Oct/2021 16:17:57] "GET /admin/ HTTP/1.1" 200 3326
C:\Users\zzajaczk\Documents\[Private]\vinder\vinder_rest_api\admin.py changed, reloading.
Watching for file changes with StatReloader
Exception in thread django-main-thread:
Traceback (most recent call last):
  File "C:\Users\zzajaczk\AppData\Local\Programs\Python\Python38\lib\threading.py", line 932, in _bootstrap_inner
    self.run()
  File "C:\Users\zzajaczk\AppData\Local\Programs\Python\Python38\lib\threading.py", line 870, in run
    self._target(*self._args, **self._kwargs)
  File "C:\Users\zzajaczk\AppData\Local\Programs\Python\Python38\lib\site-packages\django\utils\autoreload.py", line 64, in wrapper
    fn(*args, **kwargs)
  File "C:\Users\zzajaczk\AppData\Local\Programs\Python\Python38\lib\site-packages\django\core\management\commands\runserver.py", line 110, in inner_run
    autoreload.raise_last_exception()
  File "C:\Users\zzajaczk\AppData\Local\Programs\Python\Python38\lib\site-packages\django\utils\autoreload.py", line 87, in raise_last_exception
    raise _exception[1]
  File "C:\Users\zzajaczk\AppData\Local\Programs\Python\Python38\lib\site-packages\django\core\management\__init__.py", line 375, in execute
    autoreload.check_errors(django.setup)()
  File "C:\Users\zzajaczk\AppData\Local\Programs\Python\Python38\lib\site-packages\django\utils\autoreload.py", line 64, in wrapper
    fn(*args, **kwargs)
  File "C:\Users\zzajaczk\AppData\Local\Programs\Python\Python38\lib\site-packages\django\__init__.py", line 24, in setup
    apps.populate(settings.INSTALLED_APPS)
  File "C:\Users\zzajaczk\AppData\Local\Programs\Python\Python38\lib\site-packages\django\apps\registry.py", line 122, in populate
    app_config.ready()
  File "C:\Users\zzajaczk\AppData\Local\Programs\Python\Python38\lib\site-packages\django\contrib\admin\apps.py", line 27, in ready
    self.module.autodiscover()
  File "C:\Users\zzajaczk\AppData\Local\Programs\Python\Python38\lib\site-packages\django\contrib\admin\__init__.py", line 24, in autodiscover
    autodiscover_modules('admin', register_to=site)
  File "C:\Users\zzajaczk\AppData\Local\Programs\Python\Python38\lib\site-packages\django\utils\module_loading.py", line 47, in autodiscover_modules
    import_module('%s.%s' % (app_config.name, module_to_search))
  File "C:\Users\zzajaczk\AppData\Local\Programs\Python\Python38\lib\importlib\__init__.py", line 127, in import_module
    return _bootstrap._gcd_import(name[level:], package, level)
  File "<frozen importlib._bootstrap>", line 1014, in _gcd_import
  File "<frozen importlib._bootstrap>", line 991, in _find_and_load
  File "<frozen importlib._bootstrap>", line 975, in _find_and_load_unlocked
  File "<frozen importlib._bootstrap>", line 671, in _load_unlocked
  File "<frozen importlib._bootstrap_external>", line 783, in exec_module
  File "<frozen importlib._bootstrap>", line 219, in _call_with_frames_removed
  File "C:\Users\zzajaczk\Documents\[Private]\vinder\vinder_rest_api\admin.py", line 5, in <module>
    admin.site.reqister(VinderSession)
  File "C:\Users\zzajaczk\AppData\Local\Programs\Python\Python38\lib\site-packages\django\utils\functional.py", line 247, in inner
    return func(self._wrapped, *args)
AttributeError: 'AdminSite' object has no attribute 'reqister'

C:\Users\zzajaczk\Documents\[Private]\vinder>
C:\Users\zzajaczk\Documents\[Private]\vinder>python manage.py runserver
Watching for file changes with StatReloader
Performing system checks...

System check identified no issues (0 silenced).
October 31, 2021 - 16:19:32
Django version 3.2.8, using settings 'vinder.settings'
Starting development server at http://127.0.0.1:8000/
Quit the server with CTRL-BREAK.
[31/Oct/2021 16:19:34] "GET /admin/ HTTP/1.1" 200 4073
[31/Oct/2021 16:19:56] "GET /admin/vinder_rest_api/vindersession/ HTTP/1.1" 200 5110
[31/Oct/2021 16:19:56] "GET /static/admin/css/changelists.css HTTP/1.1" 200 6874
[31/Oct/2021 16:19:56] "GET /static/admin/js/jquery.init.js HTTP/1.1" 200 347
[31/Oct/2021 16:19:56] "GET /admin/jsi18n/ HTTP/1.1" 200 3195
[31/Oct/2021 16:19:56] "GET /static/admin/js/core.js HTTP/1.1" 200 5698
[31/Oct/2021 16:19:56] "GET /static/admin/js/admin/RelatedObjectLookups.js HTTP/1.1" 200 5984
[31/Oct/2021 16:19:56] "GET /static/admin/js/vendor/jquery/jquery.js HTTP/1.1" 200 287630
[31/Oct/2021 16:19:56] "GET /static/admin/js/actions.js HTTP/1.1" 200 7867
[31/Oct/2021 16:19:56] "GET /static/admin/js/urlify.js HTTP/1.1" 200 7902
[31/Oct/2021 16:19:56] "GET /static/admin/js/prepopulate.js HTTP/1.1" 200 1531
[31/Oct/2021 16:19:56] "GET /static/admin/js/vendor/xregexp/xregexp.js HTTP/1.1" 200 232381
[31/Oct/2021 16:19:56] "GET /static/admin/img/tooltag-add.svg HTTP/1.1" 200 331
[31/Oct/2021 16:19:59] "GET /admin/auth/user/ HTTP/1.1" 200 8427
[31/Oct/2021 16:19:59] "GET /admin/jsi18n/ HTTP/1.1" 200 3195
[31/Oct/2021 16:19:59] "GET /static/admin/img/search.svg HTTP/1.1" 200 458
[31/Oct/2021 16:19:59] "GET /static/admin/img/icon-yes.svg HTTP/1.1" 200 436
[31/Oct/2021 16:19:59] "GET /static/admin/img/sorting-icons.svg HTTP/1.1" 200 1097
[31/Oct/2021 16:20:13] "GET /admin/auth/user/add/ HTTP/1.1" 200 7476
[31/Oct/2021 16:20:13] "GET /static/admin/css/forms.css HTTP/1.1" 200 8804
[31/Oct/2021 16:20:13] "GET /static/admin/js/prepopulate_init.js HTTP/1.1" 200 492
[31/Oct/2021 16:20:13] "GET /admin/jsi18n/ HTTP/1.1" 200 3195
[31/Oct/2021 16:20:13] "GET /static/admin/js/change_form.js HTTP/1.1" 200 606
[31/Oct/2021 16:20:13] "GET /static/admin/css/widgets.css HTTP/1.1" 200 11097

C:\Users\zzajaczk\Documents\[Private]\vinder>
C:\Users\zzajaczk\Documents\[Private]\vinder>
C:\Users\zzajaczk\Documents\[Private]\vinder>
C:\Users\zzajaczk\Documents\[Private]\vinder>
C:\Users\zzajaczk\Documents\[Private]\vinder>
C:\Users\zzajaczk\Documents\[Private]\vinder>python manage.py shell
Python 3.8.5 (tags/v3.8.5:580fbb0, Jul 20 2020, 15:57:54) [MSC v.1924 64 bit (AMD64)] on win32
Type "help", "copyright", "credits" or "license" for more information.
(InteractiveConsole)
>>> from django.contrib.auth.models import User
>>> u1 = User()
>>> u1.username = "user1"
>>> u1.password = "user1password"
>>> u1
<User: user1>
>>> u1.save()
>>> u2 = User()
>>> u2.username = "user2"
>>> u2.password = "user2password"
>>> u2.save()
>>> exit()

C:\Users\zzajaczk\Documents\[Private]\vinder>python manage.py runserver
Watching for file changes with StatReloader
Performing system checks...

System check identified no issues (0 silenced).
October 31, 2021 - 16:23:22
Django version 3.2.8, using settings 'vinder.settings'
Starting development server at http://127.0.0.1:8000/
Quit the server with CTRL-BREAK.
[31/Oct/2021 16:23:29] "GET /admin/auth/group/ HTTP/1.1" 200 5353
[31/Oct/2021 16:23:29] "GET /static/admin/css/base.css HTTP/1.1" 304 0
[31/Oct/2021 16:23:29] "GET /static/admin/css/nav_sidebar.css HTTP/1.1" 304 0
[31/Oct/2021 16:23:29] "GET /static/admin/css/responsive.css HTTP/1.1" 304 0
[31/Oct/2021 16:23:29] "GET /admin/jsi18n/ HTTP/1.1" 200 3195
[31/Oct/2021 16:23:30] "GET /static/admin/css/fonts.css HTTP/1.1" 304 0
[31/Oct/2021 16:23:30] "GET /static/admin/js/nav_sidebar.js HTTP/1.1" 304 0
[31/Oct/2021 16:23:30] "GET /static/admin/img/icon-addlink.svg HTTP/1.1" 304 0
[31/Oct/2021 16:23:30] "GET /static/admin/fonts/Roboto-Regular-webfont.woff HTTP/1.1" 304 0
[31/Oct/2021 16:23:30] "GET /static/admin/fonts/Roboto-Light-webfont.woff HTTP/1.1" 304 0
[31/Oct/2021 16:23:30] "GET /static/admin/fonts/Roboto-Bold-webfont.woff HTTP/1.1" 304 0
[31/Oct/2021 16:23:31] "GET /admin/auth/user/ HTTP/1.1" 200 9194
[31/Oct/2021 16:23:31] "GET /admin/jsi18n/ HTTP/1.1" 200 3195
[31/Oct/2021 16:23:31] "GET /static/admin/img/icon-no.svg HTTP/1.1" 200 560
[31/Oct/2021 16:23:38] "GET /admin/auth/user/2/change/ HTTP/1.1" 200 15834
[31/Oct/2021 16:23:38] "GET /static/admin/js/calendar.js HTTP/1.1" 200 8466
[31/Oct/2021 16:23:38] "GET /admin/jsi18n/ HTTP/1.1" 200 3195
[31/Oct/2021 16:23:38] "GET /static/admin/js/SelectBox.js HTTP/1.1" 200 4360
[31/Oct/2021 16:23:38] "GET /static/admin/js/SelectFilter2.js HTTP/1.1" 200 12350
[31/Oct/2021 16:23:38] "GET /static/admin/js/admin/DateTimeShortcuts.js HTTP/1.1" 200 19634
[31/Oct/2021 16:23:39] "GET /static/admin/img/icon-unknown.svg HTTP/1.1" 200 655
[31/Oct/2021 16:23:39] "GET /static/admin/img/selector-icons.svg HTTP/1.1" 200 3291
[31/Oct/2021 16:23:39] "GET /static/admin/img/icon-calendar.svg HTTP/1.1" 200 1086
[31/Oct/2021 16:23:39] "GET /static/admin/img/icon-unknown-alt.svg HTTP/1.1" 200 655
[31/Oct/2021 16:23:39] "GET /static/admin/img/icon-clock.svg HTTP/1.1" 200 677
[31/Oct/2021 16:23:57] "GET /admin/vinder_rest_api/vindersession/ HTTP/1.1" 200 5110
[31/Oct/2021 16:23:57] "GET /admin/jsi18n/ HTTP/1.1" 200 3195
[31/Oct/2021 16:23:59] "GET /admin/vinder_rest_api/vindersession/add/ HTTP/1.1" 200 8733
[31/Oct/2021 16:23:59] "GET /admin/jsi18n/ HTTP/1.1" 200 3195
[31/Oct/2021 16:23:59] "GET /static/admin/img/icon-changelink.svg HTTP/1.1" 304 0
[31/Oct/2021 16:24:34] "POST /admin/vinder_rest_api/vindersession/add/ HTTP/1.1" 302 0
[31/Oct/2021 16:24:34] "GET /admin/vinder_rest_api/vindersession/ HTTP/1.1" 200 6546
[31/Oct/2021 16:24:34] "GET /admin/jsi18n/ HTTP/1.1" 200 3195

C:\Users\zzajaczk\Documents\[Private]\vinder>
C:\Users\zzajaczk\Documents\[Private]\vinder>
C:\Users\zzajaczk\Documents\[Private]\vinder>
C:\Users\zzajaczk\Documents\[Private]\vinder>
C:\Users\zzajaczk\Documents\[Private]\vinder>python manage.py shell
Python 3.8.5 (tags/v3.8.5:580fbb0, Jul 20 2020, 15:57:54) [MSC v.1924 64 bit (AMD64)] on win32
Type "help", "copyright", "credits" or "license" for more information.
(InteractiveConsole)
>>> from vinder_rest_api.models import VinderSession
>>> all_sessions = VinderSession.objects.all()
>>> print(all_sessions)
<QuerySet [<VinderSession: VinderSession object (1)>]>
>>> session= all_sessions[0]
>>> session.choices1
'1,2,3,4'
>>> session.init_user
<User: user1>
>>> VinderSession.objects.filter(init_user_username = "user1")
Traceback (most recent call last):
  File "<console>", line 1, in <module>
  File "C:\Users\zzajaczk\AppData\Local\Programs\Python\Python38\lib\site-packages\django\db\models\manager.py", line 85, in manager_method
    return getattr(self.get_queryset(), name)(*args, **kwargs)
  File "C:\Users\zzajaczk\AppData\Local\Programs\Python\Python38\lib\site-packages\django\db\models\query.py", line 941, in filter
    return self._filter_or_exclude(False, args, kwargs)
  File "C:\Users\zzajaczk\AppData\Local\Programs\Python\Python38\lib\site-packages\django\db\models\query.py", line 961, in _filter_or_exclude
    clone._filter_or_exclude_inplace(negate, args, kwargs)
  File "C:\Users\zzajaczk\AppData\Local\Programs\Python\Python38\lib\site-packages\django\db\models\query.py", line 968, in _filter_or_exclude_inplace
    self._query.add_q(Q(*args, **kwargs))
  File "C:\Users\zzajaczk\AppData\Local\Programs\Python\Python38\lib\site-packages\django\db\models\sql\query.py", line 1393, in add_q
    clause, _ = self._add_q(q_object, self.used_aliases)
  File "C:\Users\zzajaczk\AppData\Local\Programs\Python\Python38\lib\site-packages\django\db\models\sql\query.py", line 1412, in _add_q
    child_clause, needed_inner = self.build_filter(
  File "C:\Users\zzajaczk\AppData\Local\Programs\Python\Python38\lib\site-packages\django\db\models\sql\query.py", line 1286, in build_filter
    lookups, parts, reffed_expression = self.solve_lookup_type(arg)
  File "C:\Users\zzajaczk\AppData\Local\Programs\Python\Python38\lib\site-packages\django\db\models\sql\query.py", line 1112, in solve_lookup_type
    _, field, _, lookup_parts = self.names_to_path(lookup_splitted, self.get_meta())
  File "C:\Users\zzajaczk\AppData\Local\Programs\Python\Python38\lib\site-packages\django\db\models\sql\query.py", line 1539, in names_to_path
    raise FieldError("Cannot resolve keyword '%s' into field. "
django.core.exceptions.FieldError: Cannot resolve keyword 'init_user_username' into field. Choices are: choices1, choices2, id, init_user, init_user_id, other_user, other_user_id
>>> VinderSession.objects.filter(init_user__username = "user1")
<QuerySet [<VinderSession: VinderSession object (1)>]>
>>> VinderSession.objects.get(init_user__username = "user1")
<VinderSession: VinderSession object (1)>
>>> VinderSession.objects.filter(init_user__username = "user122")
<QuerySet []>
>>> VinderSession.objects.filter(init_user__username = "user1")
<QuerySet [<VinderSession: VinderSession object (1)>]>
>>> exit()

C:\Users\zzajaczk\Documents\[Private]\vinder>python manage.py runserver
Watching for file changes with StatReloader
Performing system checks...

System check identified no issues (0 silenced).
October 31, 2021 - 16:47:15
Django version 3.2.8, using settings 'vinder.settings'
Starting development server at http://127.0.0.1:8000/
Quit the server with CTRL-BREAK.
C:\Users\zzajaczk\Documents\[Private]\vinder\vinder_rest_api\views.py changed, reloading.
Watching for file changes with StatReloader
Performing system checks...

System check identified no issues (0 silenced).
October 31, 2021 - 16:47:54
Django version 3.2.8, using settings 'vinder.settings'
Starting development server at http://127.0.0.1:8000/
Quit the server with CTRL-BREAK.
Not Found: /vinder/get_all_sessons
[31/Oct/2021 16:48:52] "GET /vinder/get_all_sessons HTTP/1.1" 404 2487
Not Found: /vinder/get_all_session
[31/Oct/2021 16:49:16] "GET /vinder/get_all_session HTTP/1.1" 404 2487
C:\Users\zzajaczk\Documents\[Private]\vinder\vinder_rest_api\urls.py changed, reloading.
Watching for file changes with StatReloader
Performing system checks...

System check identified no issues (0 silenced).
October 31, 2021 - 16:49:48
Django version 3.2.8, using settings 'vinder.settings'
Starting development server at http://127.0.0.1:8000/
Quit the server with CTRL-BREAK.
Not Found: /vinder/get_all_session
[31/Oct/2021 16:49:50] "GET /vinder/get_all_session HTTP/1.1" 404 2498
<QuerySet [<VinderSession: VinderSession object (1)>]>
[31/Oct/2021 16:49:58] "GET /vinder/get_all_sessions HTTP/1.1" 200 27
C:\Users\zzajaczk\Documents\[Private]\vinder\vinder_rest_api\views.py changed, reloading.
<QuerySet [<VinderSession: VinderSession object (1)>]>
Watching for file changes with StatReloader
Performing system checks...

System check identified no issues (0 silenced).
October 31, 2021 - 17:03:32
Django version 3.2.8, using settings 'vinder.settings'
Starting development server at http://127.0.0.1:8000/
Quit the server with CTRL-BREAK.
[31/Oct/2021 17:03:33] "GET /vinder/get_all_sessions HTTP/1.1" 200 27
[31/Oct/2021 17:03:38] "GET /vinder/get_all_sessions HTTP/1.1" 200 27
[31/Oct/2021 17:03:48] "GET /vinder/get_all_sessions HTTP/1.1" 200 27
C:\Users\zzajaczk\Documents\[Private]\vinder\vinder_rest_api\views.py changed, reloading.
Watching for file changes with StatReloader
Performing system checks...

System check identified no issues (0 silenced).
October 31, 2021 - 17:04:23
Django version 3.2.8, using settings 'vinder.settings'
Starting development server at http://127.0.0.1:8000/
Quit the server with CTRL-BREAK.
C:\Users\zzajaczk\Documents\[Private]\vinder\vinder_rest_api\views.py changed, reloading.
Watching for file changes with StatReloader
Performing system checks...

System check identified no issues (0 silenced).
October 31, 2021 - 17:04:27
Django version 3.2.8, using settings 'vinder.settings'
Starting development server at http://127.0.0.1:8000/
Quit the server with CTRL-BREAK.
[31/Oct/2021 17:04:28] "GET /vinder/get_all_sessions HTTP/1.1" 200 133
[31/Oct/2021 17:05:08] "GET /vinder/get_all_sessions HTTP/1.1" 200 133
[31/Oct/2021 17:07:09] "GET /vinder/get_all_sessions HTTP/1.1" 200 133

C:\Users\zzajaczk\Documents\[Private]\vinder>python manage.py shell
Python 3.8.5 (tags/v3.8.5:580fbb0, Jul 20 2020, 15:57:54) [MSC v.1924 64 bit (AMD64)] on win32
Type "help", "copyright", "credits" or "license" for more information.
(InteractiveConsole)
>>> from .models import VinderSession
Traceback (most recent call last):
  File "<console>", line 1, in <module>
KeyError: "'__name__' not in globals"
>>> from django.contrib.auth.models import User
>>> u1 = User()
>>> u1.username = "user3"
>>> u1.set_password("user3")
>>> u1.save()
>>> u1 = User()
>>> u1.username = "user4"
>>> u1.set_password("user4")
>>> u1.save()
>>> exit()

C:\Users\zzajaczk\Documents\[Private]\vinder>python manage.py runserver
Watching for file changes with StatReloader
Performing system checks...

System check identified no issues (0 silenced).
October 31, 2021 - 17:11:47
Django version 3.2.8, using settings 'vinder.settings'
Starting development server at http://127.0.0.1:8000/
Quit the server with CTRL-BREAK.
[31/Oct/2021 17:12:16] "GET /vinder/get_all_sessions HTTP/1.1" 200 133
[31/Oct/2021 17:12:20] "GET /vinder/get_all_sessions HTTP/1.1" 200 133
[31/Oct/2021 17:12:26] "GET /admin/ HTTP/1.1" 200 4432
[31/Oct/2021 17:12:26] "GET /static/admin/css/base.css HTTP/1.1" 304 0
[31/Oct/2021 17:12:26] "GET /static/admin/css/nav_sidebar.css HTTP/1.1" 304 0
[31/Oct/2021 17:12:26] "GET /static/admin/css/dashboard.css HTTP/1.1" 304 0
[31/Oct/2021 17:12:26] "GET /static/admin/css/responsive.css HTTP/1.1" 304 0
[31/Oct/2021 17:12:26] "GET /static/admin/js/nav_sidebar.js HTTP/1.1" 304 0
[31/Oct/2021 17:12:26] "GET /static/admin/css/fonts.css HTTP/1.1" 304 0
[31/Oct/2021 17:12:26] "GET /static/admin/img/icon-addlink.svg HTTP/1.1" 304 0
[31/Oct/2021 17:12:26] "GET /static/admin/img/icon-changelink.svg HTTP/1.1" 304 0
[31/Oct/2021 17:12:27] "GET /static/admin/fonts/Roboto-Bold-webfont.woff HTTP/1.1" 304 0
[31/Oct/2021 17:12:27] "GET /static/admin/fonts/Roboto-Light-webfont.woff HTTP/1.1" 304 0
[31/Oct/2021 17:12:27] "GET /static/admin/fonts/Roboto-Regular-webfont.woff HTTP/1.1" 304 0
[31/Oct/2021 17:12:29] "GET /admin/auth/user/ HTTP/1.1" 200 9960
[31/Oct/2021 17:12:29] "GET /static/admin/css/changelists.css HTTP/1.1" 304 0
[31/Oct/2021 17:12:29] "GET /static/admin/js/vendor/jquery/jquery.js HTTP/1.1" 304 0
[31/Oct/2021 17:12:29] "GET /static/admin/js/core.js HTTP/1.1" 304 0
[31/Oct/2021 17:12:29] "GET /static/admin/js/jquery.init.js HTTP/1.1" 304 0
[31/Oct/2021 17:12:29] "GET /static/admin/js/admin/RelatedObjectLookups.js HTTP/1.1" 304 0
[31/Oct/2021 17:12:29] "GET /admin/jsi18n/ HTTP/1.1" 200 3195
[31/Oct/2021 17:12:29] "GET /static/admin/js/actions.js HTTP/1.1" 304 0
[31/Oct/2021 17:12:29] "GET /static/admin/js/urlify.js HTTP/1.1" 304 0
[31/Oct/2021 17:12:29] "GET /static/admin/js/prepopulate.js HTTP/1.1" 304 0
[31/Oct/2021 17:12:29] "GET /static/admin/js/vendor/xregexp/xregexp.js HTTP/1.1" 304 0
[31/Oct/2021 17:12:29] "GET /static/admin/img/search.svg HTTP/1.1" 304 0
[31/Oct/2021 17:12:29] "GET /static/admin/img/icon-yes.svg HTTP/1.1" 304 0
[31/Oct/2021 17:12:29] "GET /static/admin/img/icon-no.svg HTTP/1.1" 304 0
[31/Oct/2021 17:12:29] "GET /static/admin/img/tooltag-add.svg HTTP/1.1" 304 0
[31/Oct/2021 17:12:29] "GET /static/admin/img/sorting-icons.svg HTTP/1.1" 304 0
[31/Oct/2021 17:12:34] "GET /admin/auth/user/4/change/ HTTP/1.1" 200 15958
[31/Oct/2021 17:12:34] "GET /static/admin/css/forms.css HTTP/1.1" 304 0
[31/Oct/2021 17:12:34] "GET /static/admin/js/admin/DateTimeShortcuts.js HTTP/1.1" 304 0
[31/Oct/2021 17:12:34] "GET /static/admin/js/SelectBox.js HTTP/1.1" 304 0
[31/Oct/2021 17:12:34] "GET /static/admin/js/calendar.js HTTP/1.1" 304 0
[31/Oct/2021 17:12:34] "GET /admin/jsi18n/ HTTP/1.1" 200 3195
[31/Oct/2021 17:12:34] "GET /static/admin/js/SelectFilter2.js HTTP/1.1" 304 0
[31/Oct/2021 17:12:34] "GET /static/admin/css/widgets.css HTTP/1.1" 304 0
[31/Oct/2021 17:12:34] "GET /static/admin/js/prepopulate_init.js HTTP/1.1" 304 0
[31/Oct/2021 17:12:34] "GET /static/admin/js/change_form.js HTTP/1.1" 304 0
[31/Oct/2021 17:12:34] "GET /static/admin/img/icon-unknown.svg HTTP/1.1" 304 0
[31/Oct/2021 17:12:34] "GET /static/admin/img/selector-icons.svg HTTP/1.1" 304 0
[31/Oct/2021 17:12:34] "GET /static/admin/img/icon-unknown-alt.svg HTTP/1.1" 304 0
[31/Oct/2021 17:12:34] "GET /static/admin/img/icon-calendar.svg HTTP/1.1" 304 0
[31/Oct/2021 17:12:34] "GET /static/admin/img/icon-clock.svg HTTP/1.1" 304 0
[31/Oct/2021 17:12:46] "GET /admin/auth/user/ HTTP/1.1" 200 9960
[31/Oct/2021 17:12:46] "GET /admin/jsi18n/ HTTP/1.1" 200 3195
[31/Oct/2021 17:12:49] "GET /admin/vinder_rest_api/vindersession/ HTTP/1.1" 200 6306
[31/Oct/2021 17:12:49] "GET /admin/jsi18n/ HTTP/1.1" 200 3195
[31/Oct/2021 17:12:51] "GET /admin/vinder_rest_api/vindersession/1/change/ HTTP/1.1" 200 9198
[31/Oct/2021 17:12:51] "GET /admin/jsi18n/ HTTP/1.1" 200 3195
[31/Oct/2021 17:12:53] "GET /admin/vinder_rest_api/vindersession/ HTTP/1.1" 200 6306
[31/Oct/2021 17:12:53] "GET /admin/jsi18n/ HTTP/1.1" 200 3195
[31/Oct/2021 17:12:54] "GET /admin/vinder_rest_api/vindersession/add/ HTTP/1.1" 200 8877
[31/Oct/2021 17:12:55] "GET /admin/jsi18n/ HTTP/1.1" 200 3195
[31/Oct/2021 17:13:23] "POST /admin/vinder_rest_api/vindersession/add/ HTTP/1.1" 302 0
[31/Oct/2021 17:13:24] "GET /admin/vinder_rest_api/vindersession/ HTTP/1.1" 200 6787
[31/Oct/2021 17:13:24] "GET /admin/jsi18n/ HTTP/1.1" 200 3195
[31/Oct/2021 17:13:34] "GET /vinder/get_all_sessions HTTP/1.1" 200 251
[31/Oct/2021 17:14:03] "GET /vinder/get_all_sessions HTTP/1.1" 200 251
C:\Users\zzajaczk\Documents\[Private]\vinder\vinder_rest_api\urls.py changed, reloading.
Watching for file changes with StatReloader
Performing system checks...

Exception in thread django-main-thread:
Traceback (most recent call last):
  File "C:\Users\zzajaczk\AppData\Local\Programs\Python\Python38\lib\threading.py", line 932, in _bootstrap_inner
    self.run()
  File "C:\Users\zzajaczk\AppData\Local\Programs\Python\Python38\lib\threading.py", line 870, in run
    self._target(*self._args, **self._kwargs)
  File "C:\Users\zzajaczk\AppData\Local\Programs\Python\Python38\lib\site-packages\django\utils\autoreload.py", line 64, in wrapper
    fn(*args, **kwargs)
  File "C:\Users\zzajaczk\AppData\Local\Programs\Python\Python38\lib\site-packages\django\core\management\commands\runserver.py", line 118, in inner_run
    self.check(display_num_errors=True)
  File "C:\Users\zzajaczk\AppData\Local\Programs\Python\Python38\lib\site-packages\django\core\management\base.py", line 419, in check
    all_issues = checks.run_checks(
  File "C:\Users\zzajaczk\AppData\Local\Programs\Python\Python38\lib\site-packages\django\core\checks\registry.py", line 76, in run_checks
    new_errors = check(app_configs=app_configs, databases=databases)
  File "C:\Users\zzajaczk\AppData\Local\Programs\Python\Python38\lib\site-packages\django\core\checks\urls.py", line 13, in check_url_config
    return check_resolver(resolver)
  File "C:\Users\zzajaczk\AppData\Local\Programs\Python\Python38\lib\site-packages\django\core\checks\urls.py", line 23, in check_resolver
    return check_method()
  File "C:\Users\zzajaczk\AppData\Local\Programs\Python\Python38\lib\site-packages\django\urls\resolvers.py", line 412, in check
    for pattern in self.url_patterns:
  File "C:\Users\zzajaczk\AppData\Local\Programs\Python\Python38\lib\site-packages\django\utils\functional.py", line 48, in __get__
    res = instance.__dict__[self.name] = self.func(instance)
  File "C:\Users\zzajaczk\AppData\Local\Programs\Python\Python38\lib\site-packages\django\urls\resolvers.py", line 598, in url_patterns
    patterns = getattr(self.urlconf_module, "urlpatterns", self.urlconf_module)
  File "C:\Users\zzajaczk\AppData\Local\Programs\Python\Python38\lib\site-packages\django\utils\functional.py", line 48, in __get__
    res = instance.__dict__[self.name] = self.func(instance)
  File "C:\Users\zzajaczk\AppData\Local\Programs\Python\Python38\lib\site-packages\django\urls\resolvers.py", line 591, in urlconf_module
    return import_module(self.urlconf_name)
  File "C:\Users\zzajaczk\AppData\Local\Programs\Python\Python38\lib\importlib\__init__.py", line 127, in import_module
    return _bootstrap._gcd_import(name[level:], package, level)
  File "<frozen importlib._bootstrap>", line 1014, in _gcd_import
  File "<frozen importlib._bootstrap>", line 991, in _find_and_load
  File "<frozen importlib._bootstrap>", line 975, in _find_and_load_unlocked
  File "<frozen importlib._bootstrap>", line 671, in _load_unlocked
  File "<frozen importlib._bootstrap_external>", line 783, in exec_module
  File "<frozen importlib._bootstrap>", line 219, in _call_with_frames_removed
  File "C:\Users\zzajaczk\Documents\[Private]\vinder\vinder\urls.py", line 20, in <module>
    path("vinder/", include("vinder_rest_api.urls")),
  File "C:\Users\zzajaczk\AppData\Local\Programs\Python\Python38\lib\site-packages\django\urls\conf.py", line 34, in include
    urlconf_module = import_module(urlconf_module)
  File "C:\Users\zzajaczk\AppData\Local\Programs\Python\Python38\lib\importlib\__init__.py", line 127, in import_module
    return _bootstrap._gcd_import(name[level:], package, level)
  File "<frozen importlib._bootstrap>", line 1014, in _gcd_import
  File "<frozen importlib._bootstrap>", line 991, in _find_and_load
  File "<frozen importlib._bootstrap>", line 975, in _find_and_load_unlocked
  File "<frozen importlib._bootstrap>", line 671, in _load_unlocked
  File "<frozen importlib._bootstrap_external>", line 783, in exec_module
  File "<frozen importlib._bootstrap>", line 219, in _call_with_frames_removed
  File "C:\Users\zzajaczk\Documents\[Private]\vinder\vinder_rest_api\urls.py", line 7, in <module>
    path("user_sessions/<str:username>",views.Filters.as_view()),
AttributeError: module 'vinder_rest_api.views' has no attribute 'Filters'
C:\Users\zzajaczk\Documents\[Private]\vinder\vinder_rest_api\views.py changed, reloading.
Watching for file changes with StatReloader
Performing system checks...

System check identified no issues (0 silenced).
October 31, 2021 - 17:22:30
Django version 3.2.8, using settings 'vinder.settings'
Starting development server at http://127.0.0.1:8000/
Quit the server with CTRL-BREAK.
C:\Users\zzajaczk\Documents\[Private]\vinder\vinder_rest_api\views.py changed, reloading.
Watching for file changes with StatReloader
Performing system checks...

System check identified no issues (0 silenced).
October 31, 2021 - 17:22:38
Django version 3.2.8, using settings 'vinder.settings'
Starting development server at http://127.0.0.1:8000/
Quit the server with CTRL-BREAK.
Not Found: /vinder/user_sessions
[31/Oct/2021 17:22:45] "GET /vinder/user_sessions HTTP/1.1" 404 2680
Not Found: /favicon.ico
[31/Oct/2021 17:22:45] "GET /favicon.ico HTTP/1.1" 404 2217
{'username': 'u123'}
Internal Server Error: /vinder/user_sessions/u123
Traceback (most recent call last):
  File "C:\Users\zzajaczk\AppData\Local\Programs\Python\Python38\lib\site-packages\django\core\handlers\exception.py", line 47, in inner
    response = get_response(request)
  File "C:\Users\zzajaczk\AppData\Local\Programs\Python\Python38\lib\site-packages\django\core\handlers\base.py", line 181, in _get_response
    response = wrapped_callback(request, *callback_args, **callback_kwargs)
  File "C:\Users\zzajaczk\AppData\Local\Programs\Python\Python38\lib\site-packages\django\views\generic\base.py", line 70, in view
    return self.dispatch(request, *args, **kwargs)
  File "C:\Users\zzajaczk\AppData\Local\Programs\Python\Python38\lib\site-packages\django\views\generic\base.py", line 98, in dispatch
    return handler(request, *args, **kwargs)
  File "C:\Users\zzajaczk\Documents\[Private]\vinder\vinder_rest_api\views.py", line 32, in get
    user1_sessions = VinderSession.objects.filter(init_user_username = "user1")
  File "C:\Users\zzajaczk\AppData\Local\Programs\Python\Python38\lib\site-packages\django\db\models\manager.py", line 85, in manager_method
    return getattr(self.get_queryset(), name)(*args, **kwargs)
  File "C:\Users\zzajaczk\AppData\Local\Programs\Python\Python38\lib\site-packages\django\db\models\query.py", line 941, in filter
    return self._filter_or_exclude(False, args, kwargs)
  File "C:\Users\zzajaczk\AppData\Local\Programs\Python\Python38\lib\site-packages\django\db\models\query.py", line 961, in _filter_or_exclude
    clone._filter_or_exclude_inplace(negate, args, kwargs)
  File "C:\Users\zzajaczk\AppData\Local\Programs\Python\Python38\lib\site-packages\django\db\models\query.py", line 968, in _filter_or_exclude_inplace
    self._query.add_q(Q(*args, **kwargs))
  File "C:\Users\zzajaczk\AppData\Local\Programs\Python\Python38\lib\site-packages\django\db\models\sql\query.py", line 1393, in add_q
    clause, _ = self._add_q(q_object, self.used_aliases)
  File "C:\Users\zzajaczk\AppData\Local\Programs\Python\Python38\lib\site-packages\django\db\models\sql\query.py", line 1412, in _add_q
    child_clause, needed_inner = self.build_filter(
  File "C:\Users\zzajaczk\AppData\Local\Programs\Python\Python38\lib\site-packages\django\db\models\sql\query.py", line 1286, in build_filter
    lookups, parts, reffed_expression = self.solve_lookup_type(arg)
  File "C:\Users\zzajaczk\AppData\Local\Programs\Python\Python38\lib\site-packages\django\db\models\sql\query.py", line 1112, in solve_lookup_type
    _, field, _, lookup_parts = self.names_to_path(lookup_splitted, self.get_meta())
  File "C:\Users\zzajaczk\AppData\Local\Programs\Python\Python38\lib\site-packages\django\db\models\sql\query.py", line 1539, in names_to_path
    raise FieldError("Cannot resolve keyword '%s' into field. "
django.core.exceptions.FieldError: Cannot resolve keyword 'init_user_username' into field. Choices are: choices1, choices2, id, init_user, init_user_id, other_user, other_user_id
[31/Oct/2021 17:22:54] "GET /vinder/user_sessions/u123 HTTP/1.1" 500 116601
C:\Users\zzajaczk\Documents\[Private]\vinder\vinder_rest_api\views.py changed, reloading.
{'username': 'user1'}
Watching for file changes with StatReloader
Performing system checks...

System check identified no issues (0 silenced).
October 31, 2021 - 17:25:32
Django version 3.2.8, using settings 'vinder.settings'
Starting development server at http://127.0.0.1:8000/
Quit the server with CTRL-BREAK.
{'username': 'user1'}
Internal Server Error: /vinder/user_sessions/user1
Traceback (most recent call last):
  File "C:\Users\zzajaczk\AppData\Local\Programs\Python\Python38\lib\site-packages\django\core\handlers\exception.py", line 47, in inner
    response = get_response(request)
  File "C:\Users\zzajaczk\AppData\Local\Programs\Python\Python38\lib\site-packages\django\core\handlers\base.py", line 181, in _get_response
    response = wrapped_callback(request, *callback_args, **callback_kwargs)
  File "C:\Users\zzajaczk\AppData\Local\Programs\Python\Python38\lib\site-packages\django\views\generic\base.py", line 70, in view
    return self.dispatch(request, *args, **kwargs)
  File "C:\Users\zzajaczk\AppData\Local\Programs\Python\Python38\lib\site-packages\django\views\generic\base.py", line 98, in dispatch
    return handler(request, *args, **kwargs)
  File "C:\Users\zzajaczk\Documents\[Private]\vinder\vinder_rest_api\views.py", line 33, in get
    user_sessions = VinderSession.objects.filter(init_user_username = username)
  File "C:\Users\zzajaczk\AppData\Local\Programs\Python\Python38\lib\site-packages\django\db\models\manager.py", line 85, in manager_method
    return getattr(self.get_queryset(), name)(*args, **kwargs)
  File "C:\Users\zzajaczk\AppData\Local\Programs\Python\Python38\lib\site-packages\django\db\models\query.py", line 941, in filter
    return self._filter_or_exclude(False, args, kwargs)
  File "C:\Users\zzajaczk\AppData\Local\Programs\Python\Python38\lib\site-packages\django\db\models\query.py", line 961, in _filter_or_exclude
    clone._filter_or_exclude_inplace(negate, args, kwargs)
  File "C:\Users\zzajaczk\AppData\Local\Programs\Python\Python38\lib\site-packages\django\db\models\query.py", line 968, in _filter_or_exclude_inplace
    self._query.add_q(Q(*args, **kwargs))
  File "C:\Users\zzajaczk\AppData\Local\Programs\Python\Python38\lib\site-packages\django\db\models\sql\query.py", line 1393, in add_q
    clause, _ = self._add_q(q_object, self.used_aliases)
  File "C:\Users\zzajaczk\AppData\Local\Programs\Python\Python38\lib\site-packages\django\db\models\sql\query.py", line 1412, in _add_q
    child_clause, needed_inner = self.build_filter(
  File "C:\Users\zzajaczk\AppData\Local\Programs\Python\Python38\lib\site-packages\django\db\models\sql\query.py", line 1286, in build_filter
    lookups, parts, reffed_expression = self.solve_lookup_type(arg)
  File "C:\Users\zzajaczk\AppData\Local\Programs\Python\Python38\lib\site-packages\django\db\models\sql\query.py", line 1112, in solve_lookup_type
    _, field, _, lookup_parts = self.names_to_path(lookup_splitted, self.get_meta())
  File "C:\Users\zzajaczk\AppData\Local\Programs\Python\Python38\lib\site-packages\django\db\models\sql\query.py", line 1539, in names_to_path
    raise FieldError("Cannot resolve keyword '%s' into field. "
django.core.exceptions.FieldError: Cannot resolve keyword 'init_user_username' into field. Choices are: choices1, choices2, id, init_user, init_user_id, other_user, other_user_id
[31/Oct/2021 17:25:33] "GET /vinder/user_sessions/user1 HTTP/1.1" 500 116758
Not Found: /favicon.ico
[31/Oct/2021 17:25:33,521] - Broken pipe from ('127.0.0.1', 59186)

{'username': 'user1'}
Internal Server Error: /vinder/user_sessions/user1
Traceback (most recent call last):
  File "C:\Users\zzajaczk\AppData\Local\Programs\Python\Python38\lib\site-packages\django\core\handlers\exception.py", line 47, in inner
    response = get_response(request)
  File "C:\Users\zzajaczk\AppData\Local\Programs\Python\Python38\lib\site-packages\django\core\handlers\base.py", line 181, in _get_response
    response = wrapped_callback(request, *callback_args, **callback_kwargs)
  File "C:\Users\zzajaczk\AppData\Local\Programs\Python\Python38\lib\site-packages\django\views\generic\base.py", line 70, in view
    return self.dispatch(request, *args, **kwargs)
  File "C:\Users\zzajaczk\AppData\Local\Programs\Python\Python38\lib\site-packages\django\views\generic\base.py", line 98, in dispatch
    return handler(request, *args, **kwargs)
  File "C:\Users\zzajaczk\Documents\[Private]\vinder\vinder_rest_api\views.py", line 33, in get
    user_sessions = VinderSession.objects.filter(init_user_username = username)
  File "C:\Users\zzajaczk\AppData\Local\Programs\Python\Python38\lib\site-packages\django\db\models\manager.py", line 85, in manager_method
    return getattr(self.get_queryset(), name)(*args, **kwargs)
  File "C:\Users\zzajaczk\AppData\Local\Programs\Python\Python38\lib\site-packages\django\db\models\query.py", line 941, in filter
    return self._filter_or_exclude(False, args, kwargs)
  File "C:\Users\zzajaczk\AppData\Local\Programs\Python\Python38\lib\site-packages\django\db\models\query.py", line 961, in _filter_or_exclude
    clone._filter_or_exclude_inplace(negate, args, kwargs)
  File "C:\Users\zzajaczk\AppData\Local\Programs\Python\Python38\lib\site-packages\django\db\models\query.py", line 968, in _filter_or_exclude_inplace
    self._query.add_q(Q(*args, **kwargs))
  File "C:\Users\zzajaczk\AppData\Local\Programs\Python\Python38\lib\site-packages\django\db\models\sql\query.py", line 1393, in add_q
    clause, _ = self._add_q(q_object, self.used_aliases)
  File "C:\Users\zzajaczk\AppData\Local\Programs\Python\Python38\lib\site-packages\django\db\models\sql\query.py", line 1412, in _add_q
    child_clause, needed_inner = self.build_filter(
  File "C:\Users\zzajaczk\AppData\Local\Programs\Python\Python38\lib\site-packages\django\db\models\sql\query.py", line 1286, in build_filter
    lookups, parts, reffed_expression = self.solve_lookup_type(arg)
  File "C:\Users\zzajaczk\AppData\Local\Programs\Python\Python38\lib\site-packages\django\db\models\sql\query.py", line 1112, in solve_lookup_type
    _, field, _, lookup_parts = self.names_to_path(lookup_splitted, self.get_meta())
  File "C:\Users\zzajaczk\AppData\Local\Programs\Python\Python38\lib\site-packages\django\db\models\sql\query.py", line 1539, in names_to_path
    raise FieldError("Cannot resolve keyword '%s' into field. "
django.core.exceptions.FieldError: Cannot resolve keyword 'init_user_username' into field. Choices are: choices1, choices2, id, init_user, init_user_id, other_user, other_user_id
[31/Oct/2021 17:25:37] "GET /vinder/user_sessions/user1 HTTP/1.1" 500 116895
Not Found: /favicon.ico
[31/Oct/2021 17:25:38,010] - Broken pipe from ('127.0.0.1', 59216)

C:\Users\zzajaczk\Documents\[Private]\vinder\vinder_rest_api\views.py changed, reloading.
Watching for file changes with StatReloader
Performing system checks...

System check identified no issues (0 silenced).
October 31, 2021 - 17:26:02
Django version 3.2.8, using settings 'vinder.settings'
Starting development server at http://127.0.0.1:8000/
Quit the server with CTRL-BREAK.
{'username': 'user1'}
[31/Oct/2021 17:26:02] "GET /vinder/user_sessions/user1 HTTP/1.1" 200 133
{'username': 'user5'}
[31/Oct/2021 17:26:09] "GET /vinder/user_sessions/user5 HTTP/1.1" 200 16
C:\Users\zzajaczk\Documents\[Private]\vinder\vinder_rest_api\views.py changed, reloading.
Watching for file changes with StatReloader
Performing system checks...

Exception in thread django-main-thread:
Traceback (most recent call last):
  File "C:\Users\zzajaczk\AppData\Local\Programs\Python\Python38\lib\threading.py", line 932, in _bootstrap_inner
    self.run()
  File "C:\Users\zzajaczk\AppData\Local\Programs\Python\Python38\lib\threading.py", line 870, in run
    self._target(*self._args, **self._kwargs)
  File "C:\Users\zzajaczk\AppData\Local\Programs\Python\Python38\lib\site-packages\django\utils\autoreload.py", line 64, in wrapper
    fn(*args, **kwargs)
  File "C:\Users\zzajaczk\AppData\Local\Programs\Python\Python38\lib\site-packages\django\core\management\commands\runserver.py", line 118, in inner_run
    self.check(display_num_errors=True)
  File "C:\Users\zzajaczk\AppData\Local\Programs\Python\Python38\lib\site-packages\django\core\management\base.py", line 419, in check
    all_issues = checks.run_checks(
  File "C:\Users\zzajaczk\AppData\Local\Programs\Python\Python38\lib\site-packages\django\core\checks\registry.py", line 76, in run_checks
    new_errors = check(app_configs=app_configs, databases=databases)
  File "C:\Users\zzajaczk\AppData\Local\Programs\Python\Python38\lib\site-packages\django\core\checks\urls.py", line 13, in check_url_config
    return check_resolver(resolver)
  File "C:\Users\zzajaczk\AppData\Local\Programs\Python\Python38\lib\site-packages\django\core\checks\urls.py", line 23, in check_resolver
    return check_method()
  File "C:\Users\zzajaczk\AppData\Local\Programs\Python\Python38\lib\site-packages\django\urls\resolvers.py", line 412, in check
    for pattern in self.url_patterns:
  File "C:\Users\zzajaczk\AppData\Local\Programs\Python\Python38\lib\site-packages\django\utils\functional.py", line 48, in __get__
    res = instance.__dict__[self.name] = self.func(instance)
  File "C:\Users\zzajaczk\AppData\Local\Programs\Python\Python38\lib\site-packages\django\urls\resolvers.py", line 598, in url_patterns
    patterns = getattr(self.urlconf_module, "urlpatterns", self.urlconf_module)
  File "C:\Users\zzajaczk\AppData\Local\Programs\Python\Python38\lib\site-packages\django\utils\functional.py", line 48, in __get__
    res = instance.__dict__[self.name] = self.func(instance)
  File "C:\Users\zzajaczk\AppData\Local\Programs\Python\Python38\lib\site-packages\django\urls\resolvers.py", line 591, in urlconf_module
    return import_module(self.urlconf_name)
  File "C:\Users\zzajaczk\AppData\Local\Programs\Python\Python38\lib\importlib\__init__.py", line 127, in import_module
    return _bootstrap._gcd_import(name[level:], package, level)
  File "<frozen importlib._bootstrap>", line 1014, in _gcd_import
  File "<frozen importlib._bootstrap>", line 991, in _find_and_load
  File "<frozen importlib._bootstrap>", line 975, in _find_and_load_unlocked
  File "<frozen importlib._bootstrap>", line 671, in _load_unlocked
  File "<frozen importlib._bootstrap_external>", line 783, in exec_module
  File "<frozen importlib._bootstrap>", line 219, in _call_with_frames_removed
  File "C:\Users\zzajaczk\Documents\[Private]\vinder\vinder\urls.py", line 20, in <module>
    path("vinder/", include("vinder_rest_api.urls")),
  File "C:\Users\zzajaczk\AppData\Local\Programs\Python\Python38\lib\site-packages\django\urls\conf.py", line 34, in include
    urlconf_module = import_module(urlconf_module)
  File "C:\Users\zzajaczk\AppData\Local\Programs\Python\Python38\lib\importlib\__init__.py", line 127, in import_module
    return _bootstrap._gcd_import(name[level:], package, level)
  File "<frozen importlib._bootstrap>", line 1014, in _gcd_import
  File "<frozen importlib._bootstrap>", line 991, in _find_and_load
  File "<frozen importlib._bootstrap>", line 975, in _find_and_load_unlocked
  File "<frozen importlib._bootstrap>", line 671, in _load_unlocked
  File "<frozen importlib._bootstrap_external>", line 783, in exec_module
  File "<frozen importlib._bootstrap>", line 219, in _call_with_frames_removed
  File "C:\Users\zzajaczk\Documents\[Private]\vinder\vinder_rest_api\urls.py", line 2, in <module>
    from . import views
  File "C:\Users\zzajaczk\Documents\[Private]\vinder\vinder_rest_api\views.py", line 33
    user_sessions = VinderSession.objects.filter(init_user__username = username | other_user__username = username )
                                                                                                       ^
SyntaxError: invalid syntax
C:\Users\zzajaczk\Documents\[Private]\vinder\vinder_rest_api\views.py changed, reloading.
Watching for file changes with StatReloader
Performing system checks...

System check identified no issues (0 silenced).
October 31, 2021 - 17:32:44
Django version 3.2.8, using settings 'vinder.settings'
Starting development server at http://127.0.0.1:8000/
Quit the server with CTRL-BREAK.
{'username': 'user1'}
[31/Oct/2021 17:32:47] "GET /vinder/user_sessions/user1 HTTP/1.1" 200 251
{'username': 'user1'}
[31/Oct/2021 17:33:46] "GET /vinder/user_sessions/user1 HTTP/1.1" 200 251

C:\Users\zzajaczk\Documents\[Private]\vinder>python manage.py runserver
Watching for file changes with StatReloader
Performing system checks...

System check identified no issues (0 silenced).
October 31, 2021 - 17:42:10
Django version 3.2.8, using settings 'vinder.settings'
Starting development server at http://127.0.0.1:8000/
Quit the server with CTRL-BREAK.


https://pythonprogramming.net/django-web-development-python-tutorial/

